Workbook
Name _Toc131088033: 'IM Format'!$E$37
Name CHK_TOL: NTBA!$F$306
Name Cr: NTBA!$F$302
Name Days_month: NTBA!$F$305
Name Days_Year: 365
Name Jan_18: OFFSET([40]Formula!$C$3,,,COUNTIF([40]Formula!$B$2:$B$100,”<>”))
Name Jan_18: OFFSET([40]Formula!$C$3,,,COUNTIF([40]Formula!$B$2:$B$100,”<>”))
Name Jan_18: OFFSET([40]Formula!$C$3,,,COUNTIF([40]Formula!$B$2:$B$100,”<>”))
Name Jan_18: OFFSET([40]Formula!$C$3,,,COUNTIF([40]Formula!$B$2:$B$100,”<>”))
Name Jan_18: OFFSET([40]Formula!$C$3,,,COUNTIF([40]Formula!$B$2:$B$100,”<>”))
Name months: NTBA!$F$303
Name SCENARIOS: Capex!$F$4:$J$4
Name SCENARIOS: NTBA!$J$4:$P$4

Sheet Cells Report (2)
A1: ="Cells usage report for Model: " & $G$3 & " Sheet: " & $E$3 & " Range: " & $J$3 -> Cells usage report for Model: Sheet: Range:
D3: Sheet: | F3: Model: | I3: Range:
D5: Sheet | E5: Reference | F5: Link - model | G5: Description | H5: Comment | I5: Impact | J5: Status
B7: =IF(C7 = "", "", COUNTA(C$1:C7) & ".") -> 1. | C7: CELLS EXPORTED - cells which are exported to other sheets in the model
D9: Sheet | E9: Reference | F9: Link - model | G9: Description | H9: Comment | I9: Impact | J9: Status
J10: Pending
B14: =IF(C14 = "", "", COUNTA(C$1:C14) & ".") -> 2. | C14: CELLS USED LOCALLY - cells which are used in other calculations in the current sheet
D16: Sheet | E16: Reference | F16: Link - model | G16: Description | H16: Comment | I16: Impact | J16: Status
J17: Pending
B21: =IF(C21 = "", "", COUNTA(C$1:C21) & ".") -> 3. | C21: CELLS EXPORTED & USED LOCALLY - cells which are used in other calculations in the current sheet and also exported to other sheets
D23: Sheet | E23: Reference | F23: Link - model | G23: Description | H23: Comment | I23: Impact | J23: Status
J24: Pending
B28: =IF(C28 = "", "", COUNTA(C$1:C28) & ".") -> 4. | C28: CELLS UNUSED - cells which are not used in any calculation in the model
D30: Sheet | E30: Reference | F30: Link - model | G30: Description | H30: Comment | I30: Impact | J30: Status
J31: Pending
A35: END

Sheet Cells Report (3)
A1: ="Cells usage report for Model: " & $G$3 & " Sheet: " & $E$3 & " Range: " & $J$3 -> Cells usage report for Model: Sheet: Range:
D3: Sheet: | F3: Model: | I3: Range:
D5: Sheet | E5: Reference | F5: Link - model | G5: Description | H5: Comment | I5: Impact | J5: Status
B7: =IF(C7 = "", "", COUNTA(C$1:C7) & ".") -> 1. | C7: CELLS EXPORTED - cells which are exported to other sheets in the model
D9: Sheet | E9: Reference | F9: Link - model | G9: Description | H9: Comment | I9: Impact | J9: Status
J10: Pending
B14: =IF(C14 = "", "", COUNTA(C$1:C14) & ".") -> 2. | C14: CELLS USED LOCALLY - cells which are used in other calculations in the current sheet
D16: Sheet | E16: Reference | F16: Link - model | G16: Description | H16: Comment | I16: Impact | J16: Status
J17: Pending
B21: =IF(C21 = "", "", COUNTA(C$1:C21) & ".") -> 3. | C21: CELLS EXPORTED & USED LOCALLY - cells which are used in other calculations in the current sheet and also exported to other sheets
D23: Sheet | E23: Reference | F23: Link - model | G23: Description | H23: Comment | I23: Impact | J23: Status
J24: Pending
B28: =IF(C28 = "", "", COUNTA(C$1:C28) & ".") -> 4. | C28: CELLS UNUSED - cells which are not used in any calculation in the model
D30: Sheet | E30: Reference | F30: Link - model | G30: Description | H30: Comment | I30: Impact | J30: Status
J31: Pending
A35: END

Sheet Cells Report (4)
A1: ="Cells usage report for Model: " & $G$3 & " Sheet: " & $E$3 & " Range: " & $J$3 -> Cells usage report for Model: Sheet: Range:
D3: Sheet: | F3: Model: | I3: Range:
D5: Sheet | E5: Reference | F5: Link - model | G5: Description | H5: Comment | I5: Impact | J5: Status
B7: =IF(C7 = "", "", COUNTA(C$1:C7) & ".") -> 1. | C7: CELLS EXPORTED - cells which are exported to other sheets in the model
D9: Sheet | E9: Reference | F9: Link - model | G9: Description | H9: Comment | I9: Impact | J9: Status
J10: Pending
B14: =IF(C14 = "", "", COUNTA(C$1:C14) & ".") -> 2. | C14: CELLS USED LOCALLY - cells which are used in other calculations in the current sheet
D16: Sheet | E16: Reference | F16: Link - model | G16: Description | H16: Comment | I16: Impact | J16: Status
J17: Pending
B21: =IF(C21 = "", "", COUNTA(C$1:C21) & ".") -> 3. | C21: CELLS EXPORTED & USED LOCALLY - cells which are used in other calculations in the current sheet and also exported to other sheets
D23: Sheet | E23: Reference | F23: Link - model | G23: Description | H23: Comment | I23: Impact | J23: Status
J24: Pending
B28: =IF(C28 = "", "", COUNTA(C$1:C28) & ".") -> 4. | C28: CELLS UNUSED - cells which are not used in any calculation in the model
D30: Sheet | E30: Reference | F30: Link - model | G30: Description | H30: Comment | I30: Impact | J30: Status
J31: Pending
A35: END

Sheet Cover
B2: Madhyanchal One Infrastructure Private Limited
B4: Financial Model
B6: August 2024

Sheet Model Disclaimer
B2: Financial Model Disclaimer
B3: The financial model prepared for Madhyanchal One Infrastructure Private Limited identified in the relevant Letter of Intent has been provided to the Client and/or third party recipients (“Third Parties”) (collectively, the Recipients”) on the express understanding that: • The Model contains information and other materials that are strictly private and confidential. The Recipients agree not to disclose the Model and/or the information and other materials contained therein to any person or entity except with the prior express written consent of PwC and the Client or as may be required by law. • The Recipients acknowledge that all project assumptions, data, revenue forecasts and results contained in the Model, whether express or implied, are provided in good faith and are based on information provided to PwC by the Client and/or on the Client’s behalf. Accordingly, PwC assumes no responsibility and makes no representations with respect to the accuracy or completeness of any information provided by the Client and/or on its behalf. • The Model was prepared by PwC for the Client solely for the particular purposes of the engagement set out in the relevant Letter of Intent (“the Purpose”). PwC, its partners, directors and employees did not, in preparing the Model, intend and do not intend that any person other than the Client should rely on the Model or its preparation. Any use Third Parties or their employees may make of the Model shall be entirely at their own risk. • The Recipients agree to use the Model only for the Purpose and the Model must not be regarded as suitable for any other purpose whatsoever. • The Model must be considered in its entirety. • By retaining and using the Model, the Recipients represent to PwC that they are capable of making their own independent assessment as to the validity of the assumptions, data and results contained in the Model and the economic, financial, regulatory, legal, taxation and accounting implications of those assumptions. • The Client accepts and undertakes the risk in relation to the supply of the Model (or any part thereof) to Third Parties and undertakes not to hold PwC responsible if (i) such receipt and/or review by Third Parties results in any action at any time against the Client and/or (ii) Third Parties misuse any confidential information obtained from receipt and/or review of the Model or by way of explanation (whether given orally or in writing) from PwC. • Save to the extent that PwC has responsibility to the Client in terms of the Engagement Letter, the Recipients acknowledge and agree that PwC does not assume any liability or responsibility to the Recipients (or any of them) or to any other person for any loss, damage, cost and/or expense of any kind whatsoever arising as a result of the Recipients’ use or misuse of the Model or for any opinion, advice, recommendations, representation or information, express or implied, contained therein, notwithstanding any negligence, default or lack of care by PwC or that such loss, damage, cost and/or expense was foreseeable. • Third Parties hereby indemnify and hold PwC, its members, partners, directors, employees, related entities and agents harmless against all actions, proceedings and claims brought or threatened against PwC, its members, partners, directors, employees, related entities and agents by any person and all loss, damage, cost and/or expense (including legal expenses) relating thereto, in any way arising out of or in connection with Third Parties’ receipt and/or use of the Model or information derived from the Model as a consequence of the provision of the Model. • No independent audit of the Model has been undertaken by an independent third party. It is anticipated that the Model will be enhanced over time. • All copyright and other proprietary rights and rights of ownership in the Model shall at all times vest in and remain the property of PwC or its licensors (as appropriate).

Sheet Model_Flow 
A1: =MID(CELL("filename",A1),FIND("]",CELL("filename",A1))+1,255) -> Model_Flow
M2: Note: To navigate, press Control [
B3: KEY
C5: Sheets
E6: Input sheet
E7: Calculation sheet
E8: Output sheet
E9: Model related documentation sheet
E10: Model checks and macro sheets
C12: Cells
E13: Input cell
B16: WORK SHEET LINKAGE
E21: NTBA | I21: Time_M | M21: Financials
E22: TBA | I22: Time_A | M22: Ind AS Financials
E23: Capex | I23: Rollout | M23: Ratios
I24: Monthly Financials
I25: GST
I26: Dep & Tax
I27: Termination Value
I28: Ind AS Monthly
I29: Check
A38: ABBREVIATIONS
E39: POS | G39: Positive
E40: NTBA | G40: Non Time Based Assumptions
E41: TBA | G41: Time Based Assumptions

Sheet Index 
A1: =MID(CELL("filename",A1),FIND("]",CELL("filename",A1))+1,255) -> Index
B4: Sheet name | F4: Links | G4: Notes
B6: Output sheets
E7: Financials | F7: Financials | G7: Financials based on Indian GAAP
E8: Ind AS Financials | F8: ='Ind AS Financials'!A$1 -> Ind AS Financials | G8: Financials based on Ind As
E9: Ratios | F9: =Ratios!A$1 -> Ratios | G9: Calulation of ratios and further analysis
B11: Input sheets
E12: NTBA | F12: =NTBA!A$1 -> NTBA | G12: Non time based inputs
E13: TBA | F13: =TBA!A$1 -> TBA | G13: Time based inputs
E14: Capex | F14: =Capex!A1 -> Capex | G14: Capex Inputs
B16: Calculation sheets
E17: Time_M | F17: =Time_M!A$1 -> Time_M | G17: Calculations related to different periods used in model, flags and factors on a monthly basis
E18: Time_A | F18: =Time_A!A$1 -> Time_A | G18: Calculations related to different periods used in model, flags and factors on an annual basis
E19: GST | F19: =GST!A$1 -> GST | G19: Calculations related to GST
E20: Rollout | F20: =Rollout!A$1 -> Rollout | G20: Calculations related to Installed meters, funding , capex phasing etc.
E21: Monthly Financials | F21: ='Monthly Financials'!A$1 -> Monthly Financials | G21: Calculations related to revenue and cost.
E22: Dep & Tax | F22: ='Dep&Tax'!A$1 -> Dep&Tax | G22: Calculation related to depreciation
E23: Termination Value | F23: ='Termination Value'!A$1 -> Termination Value | G23: Calculation related to termination value
E24: Ind AS Monthly | F24: ='Ind AS Monthly'!A$1 -> Ind AS Monthly | G24: Calculation related to Leases
B26: Others
E27: Check | F27: =Check!A$1 -> Check | G27: Check sheet for various model related checks

Sheet Sensitivity
A1: =MID(CELL("filename",A1),FIND("]",CELL("filename",A1))+1,255) -> Sensitivity
C3: Scenario | D3: IRR (%) | E3: DSCR (min) | F3: DSCR (Avg) | H3: Scenario | I3: Details | J3: Quantum
C4: 1 | D4: =Ratios!F72 -> 0.12614221 | E4: =Ratios!F35 -> 1.1507718 | F4: =Ratios!F34 -> 1.2018678 | H4: 1 | I4: Base Case
H5: 2 | I5: Increase in Interest Rate by __ | J5: 0.005
H6: 3 | I6: Decrease in revenue from Operation by __ | J6: 0.1
H7: 4 | I7: Increase in Project Cost by __ | J7: 0.1
H8: 5 | I8: Increase in interest rate by __ & decrease in revenue by __ | J8: 0.50% and 10%

Sheet NTBA
A1: =RIGHT(CELL("FILENAME", $A$1), LEN(CELL("FILENAME", $A$1)) - SEARCH("]", CELL("FILENAME", $A$1))) -> NTBA | J1: [don't del col] | P1: [don't del col]
E2: =Check!F$3 -> Model Check | F2: =Check!G$3 -> 0 | G2: =Check!H$3 -> check
E4: Scenario selection | F4: =Sensitivity!C4 -> 1 | K4: 1 | L4: 2 | M4: 3 | N4: 4 | O4: 5
E5: Scenario Description | F5: {=INDEX($K5:$O5, , MATCH($F4, $K$4:$O$4,))} -> Scenario 1 | K5: Scenario 1 | L5: Scenario 2 | M5: Scenario 3 | N5: Scenario 4 | O5: Scenario 5
E7: Particulars | F7: Constant | G7: Unit | H7: Source | J7: [Range start] | P7: [Range end] | R7: Remarks
A9: TIMELINE
B11: Timeline setup
E12: 1st model column start date | F12: =INDEX($K12:$O12, MATCH($F$4, $K$4:$O$4, 0)) -> 45323 | G12: date | K12: 45323 | L12: 45323 | M12: 45323 | N12: 45323 | O12: 45323
E13: 1st model column financial year | F13: =INDEX($K13:$O13, MATCH($F$4, $K$4:$O$4, 0)) -> 2024 | G13: year | K13: =IF(MONTH(K12) <4, YEAR(K12), YEAR(K12) + 1) -> 2024 | L13: =IF(MONTH(L12) <4, YEAR(L12), YEAR(L12) + 1) -> 2024 | M13: =IF(MONTH(M12) <4, YEAR(M12), YEAR(M12) + 1) -> 2024 | N13: =IF(MONTH(N12) <4, YEAR(N12), YEAR(N12) + 1) -> 2024 | O13: =IF(MONTH(O12) <4, YEAR(O12), YEAR(O12) + 1) -> 2024
B15: Construction timeline
E16: Timeline for commencement of meter installation | F16: =INDEX($K16:$O16, MATCH($F$4, $K$4:$O$4, 0)) -> 5 | G16: months | K16: 5 | L16: 5 | M16: 5 | N16: 5 | O16: 5
E17: Construction start date | F17: =INDEX($K17:$O17, MATCH($F$4, $K$4:$O$4, 0)) -> 45474 | G17: date | K17: =EDATE( K12, K16) -> 45474 | L17: =EDATE( L12, L16) -> 45474 | M17: =EDATE( M12, M16) -> 45474 | N17: =EDATE( N12, N16) -> 45474 | O17: =EDATE( O12, O16) -> 45474
E18: Construction tenure | F18: =INDEX($K18:$O18, MATCH($F$4, $K$4:$O$4, 0)) -> 22 | G18: months | K18: =27-K16 -> 22 | L18: =27-L16 -> 22 | M18: =27-M16 -> 22 | N18: =27-N16 -> 22 | O18: =27-O16 -> 22
E19: Construction end date | F19: =INDEX($K19:$O19, MATCH($F$4, $K$4:$O$4, 0)) -> 46173 | G19: date | K19: =EOMONTH( K17, K18) -> 46173 | L19: =EOMONTH( L17, L18) -> 46173 | M19: =EOMONTH( M17, M18) -> 46173 | N19: =EOMONTH( N17, N18) -> 46173 | O19: =EOMONTH( O17, O18) -> 46173
E20: Construction start date FY | F20: =INDEX($K20:$O20, MATCH($F$4, $K$4:$O$4, 0)) -> 45747 | G20: date | K20: =DATE( IF( MONTH( K17 ) <= 3,YEAR( K17 ), YEAR( K17 ) + 1), 3, 31 ) -> 45747 | L20: =DATE( IF( MONTH( L17 ) <= 3,YEAR( L17 ), YEAR( L17 ) + 1), 3, 31 ) -> 45747 | M20: =DATE( IF( MONTH( M17 ) <= 3,YEAR( M17 ), YEAR( M17 ) + 1), 3, 31 ) -> 45747 | N20: =DATE( IF( MONTH( N17 ) <= 3,YEAR( N17 ), YEAR( N17 ) + 1), 3, 31 ) -> 45747 | O20: =DATE( IF( MONTH( O17 ) <= 3,YEAR( O17 ), YEAR( O17 ) + 1), 3, 31 ) -> 45747
B22: Operation timeline
E23: Operation start date | F23: =INDEX($K23:$O23, MATCH($F$4, $K$4:$O$4, 0)) -> 46174 | G23: date | K23: =K19+1 -> 46174 | L23: =L19+1 -> 46174 | M23: =M19+1 -> 46174 | N23: =N19+1 -> 46174 | O23: =O19+1 -> 46174
E24: Operation tenure | F24: =INDEX($K24:$O24, MATCH($F$4, $K$4:$O$4, 0)) -> 85 | G24: months | K24: =ROUND( ( K25 - K23 ) / Days_month-1, ) -> 85 | L24: =ROUND( ( L25 - L23 ) / Days_month-1, ) -> 85 | M24: =ROUND( ( M25 - M23 ) / Days_month-1, ) -> 85 | N24: =ROUND( ( N25 - N23 ) / Days_month-1, ) -> 85 | O24: =ROUND( ( O25 - O23 ) / Days_month-1, ) -> 85
E25: Operation end date | F25: =INDEX($K25:$O25, MATCH($F$4, $K$4:$O$4, 0)) -> 48760 | G25: date | K25: =Rollout!$F$46 -> 48760 | L25: =Rollout!$F$46 -> 48760 | M25: =Rollout!$F$46 -> 48760 | N25: =Rollout!$F$46 -> 48760 | O25: =Rollout!$F$46 -> 48760
E26: Operation end date FY | F26: =INDEX($K26:$O26, MATCH($F$4, $K$4:$O$4, 0)) -> 49034 | G26: date | K26: =DATE( IF(MONTH( K25 ) <=3, YEAR( K25 ), YEAR( K25) + 1), 3, 31 ) -> 49034 | L26: =DATE( IF(MONTH( L25 ) <=3, YEAR( L25 ), YEAR( L25) + 1), 3, 31 ) -> 49034 | M26: =DATE( IF(MONTH( M25 ) <=3, YEAR( M25 ), YEAR( M25) + 1), 3, 31 ) -> 49034 | N26: =DATE( IF(MONTH( N25 ) <=3, YEAR( N25 ), YEAR( N25) + 1), 3, 31 ) -> 49034 | O26: =DATE( IF(MONTH( O25 ) <=3, YEAR( O25 ), YEAR( O25) + 1), 3, 31 ) -> 49034
E27: Total Implementation Period | F27: =INDEX($K27:$O27, MATCH($F$4, $K$4:$O$4, 0)) -> 112 | G27: Months | K27: =K24 + K18+K16 -> 112 | L27: =L24 + L18+L16 -> 112 | M27: =M24 + M18+M16 -> 112 | N27: =N24 + N18+N16 -> 112 | O27: =O24 + O18+O16 -> 112
A31: REVENUE
B33: Smart Meter
E34: No of Meter Months for SBD | F34: =INDEX($K34:$O34, MATCH($F$4, $K$4:$O$4, 0)) -> 93 | G34: Nos. | K34: 93 | L34: 93 | M34: 93 | N34: 93 | O34: 93
E35: Total number of meter months for billing for SBD | F35: =INDEX($K35:$O35, MATCH($F$4, $K$4:$O$4, 0)) -> 257411724 | G35: Nos. | K35: =NTBA!K85 * NTBA!K34 -> 257411724 | L35: =NTBA!L85 * NTBA!L34 -> 257411724 | M35: =NTBA!M85 * NTBA!M34 -> 257411724 | N35: =NTBA!N85 * NTBA!N34 -> 257411724 | O35: =NTBA!O85 * NTBA!O34 -> 257411724
E36: Upfront Payment on Smart Meter - Consumer Meters | F36: =INDEX($K36:$O36, MATCH($F$4, $K$4:$O$4, 0)) -> 762.71186 | G36: INR / meter | K36: =900/1.18 -> 762.71186 | L36: =900/1.18 -> 762.71186 | M36: =900/1.18 -> 762.71186 | N36: =900/1.18 -> 762.71186 | O36: =900/1.18 -> 762.71186
E37: Upfront Payment on Smart Meter - DT Meters | F37: =INDEX($K37:$O37, MATCH($F$4, $K$4:$O$4, 0)) -> 2923.7288 | G37: INR / meter | K37: =3450/1.18 -> 2923.7288 | L37: =3450/1.18 -> 2923.7288 | M37: =3450/1.18 -> 2923.7288 | N37: =3450/1.18 -> 2923.7288 | O37: =3450/1.18 -> 2923.7288
E38: Upfront Payment on Smart Meter - Feeder Meters | F38: =INDEX($K38:$O38, MATCH($F$4, $K$4:$O$4, 0)) -> 5338.9831 | G38: INR / meter | K38: =6300/1.18 -> 5338.9831 | L38: =6300/1.18 -> 5338.9831 | M38: =6300/1.18 -> 5338.9831 | N38: =6300/1.18 -> 5338.9831 | O38: =6300/1.18 -> 5338.9831
E39: Qouted - Avg. Service Charge (PMPM) | F39: =INDEX($K39:$O39, MATCH($F$4, $K$4:$O$4, 0)) -> 79.560181 | G39: INR / meter / month | K39: 79.560181 | L39: 79.560181 | M39: =79.560181*(1-Sensitivity!$J$6) -> 71.604163 | N39: 79.560181 | O39: =79.560181*(1-Sensitivity!$J$6) -> 71.604163
E40: GST on AMISP Service Charge (In %) | F40: =INDEX($K40:$O40, MATCH($F$4, $K$4:$O$4, 0)) -> 0.18 | G40: % | K40: 0.18 | L40: 0.18 | M40: 0.18 | N40: 0.18 | O40: 0.18
B42: Revenue Schedule (Post-Installation)
E43: First Payment | F43: =INDEX($K43:$O43, MATCH($F$4, $K$4:$O$4, 0)) -> 1 | G43: % | K43: 1 | L43: 1 | M43: 1 | N43: 1 | O43: 1
E44: Second Payment | F44: =INDEX($K44:$O44, MATCH($F$4, $K$4:$O$4, 0)) -> 0 | G44: % | K44: 0 | L44: 0 | M44: 0 | N44: 0 | O44: 0
E45: Final Payment | F45: =INDEX($K45:$O45, MATCH($F$4, $K$4:$O$4, 0)) -> 0 | G45: % | K45: 0 | L45: 0 | M45: 0 | N45: 0 | O45: 0
E46: Total | F46: =INDEX($K46:$O46, MATCH($F$4, $K$4:$O$4, 0)) -> 1 | G46: % | K46: =SUM(K43:K45) -> 1 | L46: =SUM(L43:L45) -> 1 | M46: =SUM(M43:M45) -> 1 | N46: =SUM(N43:N45) -> 1 | O46: =SUM(O43:O45) -> 1
E48: First Payment | F48: =INDEX($K48:$O48, MATCH($F$4, $K$4:$O$4, 0)) -> 0 | G48: months | K48: 0 | L48: 0 | M48: 0 | N48: 0 | O48: 0
E49: Second Payment | F49: =INDEX($K49:$O49, MATCH($F$4, $K$4:$O$4, 0)) -> 0 | G49: months | K49: 0 | L49: 0 | M49: 0 | N49: 0 | O49: 0
E50: Final Payment | F50: =INDEX($K50:$O50, MATCH($F$4, $K$4:$O$4, 0)) -> 0 | G50: months | K50: 0 | L50: 0 | M50: 0 | N50: 0 | O50: 0
E52: Upfront Payment (post COD) | F52: =INDEX($K52:$O52, MATCH($F$4, $K$4:$O$4, 0)) -> 3 | G52: months | K52: 3 | L52: 3 | M52: 3 | N52: 3 | O52: 3 | R52: Note: Maximum delay in payment assumed as 3 months
E54: First Payment Milestone (% of meters installed) | F54: =INDEX($K54:$O54, MATCH($F$4, $K$4:$O$4, 0)) -> 0.01 | G54: % | K54: 0.01 | L54: 0.01 | M54: 0.01 | N54: 0.01 | O54: 0.01
...

Sheet Capex
A1: =RIGHT(CELL("FILENAME", $A$1), LEN(CELL("FILENAME", $A$1)) - SEARCH("]", CELL("FILENAME", $A$1))) -> Capex
E4: Increase in Project Cost (sensitivity) | F4: =IF(Sensitivity!C4=4,Sensitivity!J7,0) -> 0
A7: CAPEX
F8: GPRS & RF | I8: RF
F9: Weighted Average Unit Rate ( INR ) | G9: Qty | H9: Amount | I9: Unit Rate ( INR ) | J9: Qty | K9: Amount
B10: A | C10: AMI Equipment Cost | G10: =G12 -> 0 | H10: =H12 + H23 -> 935.53938 | J10: =J12 + J23 -> 0 | K10: =K12 + K23 -> 0
D12: Smart Meter Energy | H12: =H14 + H17+ H20 -> 935.53938 | J12: =J14 + J17 + J20 -> 0 | K12: =K14 + K17+ K20 -> 0
D14: Consumer Meters | G14: =SUM(G15:G15) -> 2767868 | H14: =SUM(H15:H15) -> 935.53938 | J14: =SUM(J15:J15) -> 0 | K14: =SUM(K15:K15) -> 0
E15: Consumer Meters | F15: =3380*(1+$F$4) -> 3380 | G15: =NTBA!K74 -> 2767868 | H15: =F15 * G15 / 10^7 -> 935.53938 | K15: =I15 * J15 / 10^7 -> 0
D17: DT Meters | G17: =SUM(G18:G18) -> 0 | H17: =SUM(H18:H18) -> 0 | J17: =SUM(J18:J18) -> 0 | K17: =SUM(K18:K18) -> 0
E18: DT Meeters | F18: 0 | G18: 0 | H18: =F18 * G18 / 10^7 -> 0 | K18: =I18 * J18 / 10^7 -> 0
D20: Feeder Meters | G20: =SUM(G21:G21) -> 0 | H20: =SUM(H21:H21) -> 0 | J20: =SUM(J21:J21) -> 0 | K20: =SUM(K21:K21) -> 0
E21: Feeder Meters | F21: 0 | G21: 0 | H21: =F21 * G21 / 10^7 -> 0 | K21: =I21 * J21 / 10^7 -> 0
D23: Smart Meter Box
E24: For Consumer Meters | F24: 0 | G24: 0 | H24: =F24 * G24 / 10^7 -> 0 | I24: 0 | J24: =J14 -> 0 | K24: =I24 * J24 / 10^7 -> 0
E25: For DT Meters | F25: 0 | G25: =G17 -> 0 | H25: =F25 * G25 / 10^7 -> 0 | I25: 0 | J25: =J17 -> 0 | K25: =I25 * J25 / 10^7 -> 0
E26: For Feeder Meters | F26: 0 | G26: =G20 -> 0 | H26: =F26 * G26 / 10^7 -> 0 | I26: 0 | J26: =J20 -> 0 | K26: =I26 * J26 / 10^7 -> 0
B28: B | C28: Corporate, Consumer Indexing & Training | H28: =SUM(H30:H31) -> 7.89881 | K28: =SUM(K30:K31) -> 0
E30: Corporate Cost | F30: 0 | G30: 0 | H30: =F30 * G30 / 10^7 -> 0 | I30: 0 | J30: 0 | K30: =I30 * J30 / 10^7 -> 0
E31: Consumer Indexing Charges & Training Cost | F31: =78988100*(1+F4) -> 78988100 | G31: 1 | H31: =F31 * G31 / 10^7 -> 7.89881 | I31: 0 | J31: 1 | K31: =I31 * J31 / 10^7 -> 0
B33: C | C33: Advanced Metering Infrastructure (AMI) IT | H33: =H35 -> 11.836221 | K33: =K35 -> 0
E34: `
D35: Application Software | H35: =SUM(H37:H40) -> 11.836221 | K35: =SUM(K37:K40) -> 0
E37: Head End System software | F37: =19796345.91*(1+F4) -> 19796346 | G37: 1 | H37: =F37 * G37 / 10^7 -> 1.9796346 | I37: 0 | J37: 1 | K37: =I37 * J37 / 10^7 -> 0
E38: Meter Data Management software (MDM) | F38: =49635000*(1+F4) -> 49635000 | G38: 1 | H38: =F38 * G38 / 10^7 -> 4.9635 | I38: 0 | J38: 1 | K38: =I38 * J38 / 10^7 -> 0
E39: Network Monitoring & Operation Center (NMOC) | F39: =6789540*(1+F4) -> 6789540 | G39: 1 | H39: =F39 * G39 / 10^7 -> 0.678954 | I39: 0 | J39: 1 | K39: =I39 * J39 / 10^7 -> 0
E40: Any Other | F40: =42141322.31695*(1+F4) -> 42141322 | G40: 1 | H40: =F40 * G40 / 10^7 -> 4.2141322 | I40: 0 | J40: 1 | K40: =I40 * J40 / 10^7 -> 0
B42: D | C42: Installation Charges | H42: =SUM( H44:H44) -> 79.394203
E44: Installation charges for All meters | F44: =793942032.45*(1+F4) -> 7.9394203e+08 | G44: 1 | H44: =F44 * G44 / 10^7 -> 79.394203 | I44: 0 | J44: 1 | K44: =I44 * J44 / 10^7 -> 0
B47: Capex Base Amount
E48: GST on Capex (In %) | F48: 0.18 | G48: In %
E50: AMI Equipment Cost | F50: =Capex!$H$10 -> 935.53938 | G50: =Capex!F50 * Capex!$F$48 -> 168.39709 | H50: =Capex!F50 + Capex!G50 -> 1103.9365
E51: Corporate, Consumer Indexing & Training | F51: =Capex!$H$28 -> 7.89881 | G51: =Capex!F51 * Capex!$F$48 -> 1.4217858 | H51: =Capex!F51 + Capex!G51 -> 9.3205958
E52: Advanced Metering Infrastructure (AMI) IT | F52: =Capex!$H$33 -> 11.836221 | G52: =Capex!F52 * Capex!$F$48 -> 2.1305197 | H52: =Capex!F52 + Capex!G52 -> 13.966741
E53: Installation Charges | F53: =Capex!$H$42 -> 79.394203 | G53: =Capex!F53 * Capex!$F$48 -> 14.290957 | H53: =Capex!F53 + Capex!G53 -> 93.68516
E54: Armoured Cables | F54: =474.620390121488*(1-F80) -> 0 | G54: =Capex!F54 * Capex!$F$48 -> 0 | H54: =Capex!F54 + Capex!G54 -> 0
E55: Contingencies | F55: =16.7031242932969*(1+F4) -> 16.703124 | G55: =Capex!F55 * Capex!$F$48 -> 3.0065624 | H55: =Capex!F55 + Capex!G55 -> 19.709687
E56: Total Capex | F56: =SUM(F50:F55) -> 1051.3717 | G56: =SUM(G50:G55) -> 189.24691 | H56: =SUM( H50:H55 ) -> 1240.6187
E58: Financing Charges - Capex | F58: =NTBA!F227 * NTBA!F201 -> 7.0251091 | G58: INR Cr
E59: Financing Charges - GST | F59: =Capex!F58 * Capex!$F$48 -> 1.2645196 | G59: INR Cr
...

Sheet TBA
A1: =RIGHT(CELL("FILENAME", $A$1), LEN(CELL("FILENAME", $A$1)) - SEARCH("]", CELL("FILENAME", $A$1))) -> TBA
E2: =Time_M!E$2 -> Model period beginning_M | J2: =Time_M!J$2 -> 45323 | K2: =Time_M!K$2 -> 45352 | L2: =Time_M!L$2 -> 45383 | M2: =Time_M!M$2 -> 45413 | N2: =Time_M!N$2 -> 45444 | O2: =Time_M!O$2 -> 45474 | P2: =Time_M!P$2 -> 45505 | Q2: =Time_M!Q$2 -> 45536 | ... EH2: =Time_M!EH$2 -> 49218
E3: =Time_M!E$3 -> Model period ending_M | F3: =Check!E$10 -> Model Check | G3: =Check!F$10 -> 0 | H3: =Check!G$10 -> check | J3: =Time_M!J$3 -> 45351 | K3: =Time_M!K$3 -> 45382 | L3: =Time_M!L$3 -> 45412 | M3: =Time_M!M$3 -> 45443 | N3: =Time_M!N$3 -> 45473 | O3: =Time_M!O$3 -> 45504 | P3: =Time_M!P$3 -> 45535 | Q3: =Time_M!Q$3 -> 45565 | ... EH3: =Time_M!EH$3 -> 49248
E4: =Time_M!E$4 -> Financial year ending period_M | J4: =Time_M!J$4 -> 45382 | K4: =Time_M!K$4 -> 45382 | L4: =Time_M!L$4 -> 45747 | M4: =Time_M!M$4 -> 45747 | N4: =Time_M!N$4 -> 45747 | O4: =Time_M!O$4 -> 45747 | P4: =Time_M!P$4 -> 45747 | Q4: =Time_M!Q$4 -> 45747 | ... EH4: =Time_M!EH$4 -> 49399
E5: =Time_M!E$5 -> Financial year ending_M | F5: Constant | G5: Unit | H5: Total | J5: =Time_M!J$5 -> 2024 | K5: =Time_M!K$5 -> 2024 | L5: =Time_M!L$5 -> 2025 | M5: =Time_M!M$5 -> 2025 | N5: =Time_M!N$5 -> 2025 | O5: =Time_M!O$5 -> 2025 | P5: =Time_M!P$5 -> 2025 | Q5: =Time_M!Q$5 -> 2025 | ... EH5: =Time_M!EH$5 -> 2035
A7: SMART METER ENERGY PHASING
B9: Hardcoded data to be inputted
C10: GPRS & RF
E11: Consumer Meter | G11: Nos. | H11: =SUM(J11:EH11) -> 2620466 | J11: 0 | K11: 0 | L11: 0 | M11: 0 | N11: 0 | O11: 3 | P11: 15000 | Q11: 30000 | R11: 70000 | S11: 80000 | T11: 80000 | U11: 80000 | V11: 100000 | W11: 120000 | X11: 140000 | Y11: 160000 | Z11: 180000 | AA11: 183000 | AB11: 155000 | AC11: 155000 | AD11: 155000 | AE11: 155000 | AF11: 155000 | AG11: 155000 | AH11: 155000 | AI11: 155000 | AJ11: 142463 | AK11: 0 | AL11: 0 | AM11: 0 | AN11: 0 | AO11: 0 | AP11: 0 | AQ11: 0 | AR11: 0 | AS11: 0 | AT11: 0 | AU11: 0 | AV11: 0 | AW11: 0 | AX11: 0 | AY11: 0 | AZ11: 0 | BA11: 0 | BB11: 0 | BC11: 0 | BD11: 0 | BE11: 0 | BF11: 0 | BG11: 0 | BH11: 0 | BI11: 0 | BJ11: 0 | BK11: 0 | BL11: 0 | BM11: 0 | BN11: 0 | BO11: 0 | BP11: 0 | BQ11: 0 | BR11: 0 | BS11: 0 | BT11: 0 | BU11: 0 | BV11: 0 | BW11: 0 | BX11: 0 | BY11: 0 | BZ11: 0 | CA11: 0 | CB11: 0 | CC11: 0 | CD11: 0 | CE11: 0 | CF11: 0 | CG11: 0 | CH11: 0 | CI11: 0 | CJ11: 0 | CK11: 0 | CL11: 0 | CM11: 0 | CN11: 0 | CO11: 0 | CP11: 0 | CQ11: 0 | CR11: 0 | CS11: 0 | CT11: 0 | CU11: 0 | CV11: 0 | CW11: 0 | CX11: 0 | CY11: 0 | CZ11: 0 | DA11: 0 | DB11: 0 | DC11: 0 | DD11: 0 | DE11: 0 | DF11: 0 | DG11: 0 | DH11: 0 | DI11: 0 | DJ11: 0 | DK11: 0 | DL11: 0 | DM11: 0 | DN11: 0 | DO11: 0 | DP11: 0 | DQ11: 0 | DR11: 0 | DS11: 0 | DT11: 0 | DU11: 0 | DV11: 0 | DW11: 0 | DX11: 0 | DY11: 0 | DZ11: 0 | EA11: 0 | EB11: 0 | EC11: 0 | ED11: 0 | EE11: 0 | EF11: 0 | EG11: 0 | EH11: 0 | EI11: 0
E12: DT Meter | G12: Nos. | H12: =SUM(J12:EH12) -> 146932 | J12: 0 | K12: 0 | L12: 0 | M12: 0 | N12: 0 | O12: 41 | P12: 800 | Q12: 3000 | R12: 8000 | S12: 8000 | T12: 8000 | U12: 8000 | V12: 8000 | W12: 10000 | X12: 15000 | Y12: 18000 | Z12: 25000 | AA12: 35091 | AB12: 0 | AC12: 0 | AD12: 0 | AE12: 0 | AF12: 0 | AG12: 0 | AH12: 0 | AI12: 0 | AJ12: 0 | AK12: 0 | AL12: 0 | AM12: 0 | AN12: 0 | AO12: 0 | AP12: 0 | AQ12: 0 | AR12: 0 | AS12: 0 | AT12: 0 | AU12: 0 | AV12: 0 | AW12: 0 | AX12: 0 | AY12: 0 | AZ12: 0 | BA12: 0 | BB12: 0 | BC12: 0 | BD12: 0 | BE12: 0 | BF12: 0 | BG12: 0 | BH12: 0 | BI12: 0 | BJ12: 0 | BK12: 0 | BL12: 0 | BM12: 0 | BN12: 0 | BO12: 0 | BP12: 0 | BQ12: 0 | BR12: 0 | BS12: 0 | BT12: 0 | BU12: 0 | BV12: 0 | BW12: 0 | BX12: 0 | BY12: 0 | BZ12: 0 | CA12: 0 | CB12: 0 | CC12: 0 | CD12: 0 | CE12: 0 | CF12: 0 | CG12: 0 | CH12: 0 | CI12: 0 | CJ12: 0 | CK12: 0 | CL12: 0 | CM12: 0 | CN12: 0 | CO12: 0 | CP12: 0 | CQ12: 0 | CR12: 0 | CS12: 0 | CT12: 0 | CU12: 0 | CV12: 0 | CW12: 0 | CX12: 0 | CY12: 0 | CZ12: 0 | DA12: 0 | DB12: 0 | DC12: 0 | DD12: 0 | DE12: 0 | DF12: 0 | DG12: 0 | DH12: 0 | DI12: 0 | DJ12: 0 | DK12: 0 | DL12: 0 | DM12: 0 | DN12: 0 | DO12: 0 | DP12: 0 | DQ12: 0 | DR12: 0 | DS12: 0 | DT12: 0 | DU12: 0 | DV12: 0 | DW12: 0 | DX12: 0 | DY12: 0 | DZ12: 0 | EA12: 0 | EB12: 0 | EC12: 0 | ED12: 0 | EE12: 0 | EF12: 0 | EG12: 0 | EH12: 0 | EI12: 0
E13: Feeder Meter | G13: Nos. | H13: =SUM(J13:EH13) -> 470 | J13: 0 | K13: 0 | L13: 0 | M13: 0 | N13: 0 | O13: 186 | P13: 84 | Q13: 200 | R13: 0 | S13: 0 | T13: 0 | U13: 0 | V13: 0 | W13: 0 | X13: 0 | Y13: 0 | Z13: 0 | AA13: 0 | AB13: 0 | AC13: 0 | AD13: 0 | AE13: 0 | AF13: 0 | AG13: 0 | AH13: 0 | AI13: 0 | AJ13: 0 | AK13: 0 | AL13: 0 | AM13: 0 | AN13: 0 | AO13: 0 | AP13: 0 | AQ13: 0 | AR13: 0 | AS13: 0 | AT13: 0 | AU13: 0 | AV13: 0 | AW13: 0 | AX13: 0 | AY13: 0 | AZ13: 0 | BA13: 0 | BB13: 0 | BC13: 0 | BD13: 0 | BE13: 0 | BF13: 0 | BG13: 0 | BH13: 0 | BI13: 0 | BJ13: 0 | BK13: 0 | BL13: 0 | BM13: 0 | BN13: 0 | BO13: 0 | BP13: 0 | BQ13: 0 | BR13: 0 | BS13: 0 | BT13: 0 | BU13: 0 | BV13: 0 | BW13: 0 | BX13: 0 | BY13: 0 | BZ13: 0 | CA13: 0 | CB13: 0 | CC13: 0 | CD13: 0 | CE13: 0 | CF13: 0 | CG13: 0 | CH13: 0 | CI13: 0 | CJ13: 0 | CK13: 0 | CL13: 0 | CM13: 0 | CN13: 0 | CO13: 0 | CP13: 0 | CQ13: 0 | CR13: 0 | CS13: 0 | CT13: 0 | CU13: 0 | CV13: 0 | CW13: 0 | CX13: 0 | CY13: 0 | CZ13: 0 | DA13: 0 | DB13: 0 | DC13: 0 | DD13: 0 | DE13: 0 | DF13: 0 | DG13: 0 | DH13: 0 | DI13: 0 | DJ13: 0 | DK13: 0 | DL13: 0 | DM13: 0 | DN13: 0 | DO13: 0 | DP13: 0 | DQ13: 0 | DR13: 0 | DS13: 0 | DT13: 0 | DU13: 0 | DV13: 0 | DW13: 0 | DX13: 0 | DY13: 0 | DZ13: 0 | EA13: 0 | EB13: 0 | EC13: 0 | ED13: 0 | EE13: 0 | EF13: 0 | EG13: 0 | EH13: 0 | EI13: 0
C15: RF
E16: Consumer Meter | G16: Nos. | H16: =SUM(J16:EH16) -> 0 | J16: 0 | K16: 0 | L16: 0 | M16: 0 | N16: 0 | O16: 0 | P16: 0 | Q16: 0 | R16: 0 | S16: 0 | T16: 0 | U16: 0 | V16: 0 | W16: 0 | X16: 0 | Y16: 0 | Z16: 0 | AA16: 0 | AB16: 0 | AC16: 0 | AD16: 0 | AE16: 0 | AF16: 0 | AG16: 0 | AH16: 0 | AI16: 0 | AJ16: 0 | AK16: 0 | AL16: 0 | AM16: 0 | AN16: 0 | AO16: 0 | AP16: 0 | AQ16: 0 | AR16: 0 | AS16: 0 | AT16: 0 | AU16: 0 | AV16: 0 | AW16: 0 | AX16: 0 | AY16: 0 | AZ16: 0 | BA16: 0 | BB16: 0 | BC16: 0 | BD16: 0 | BE16: 0 | BF16: 0 | BG16: 0 | BH16: 0 | BI16: 0 | BJ16: 0 | BK16: 0 | BL16: 0 | BM16: 0 | BN16: 0 | BO16: 0 | BP16: 0 | BQ16: 0 | BR16: 0 | BS16: 0 | BT16: 0 | BU16: 0 | BV16: 0 | BW16: 0 | BX16: 0 | BY16: 0 | BZ16: 0 | CA16: 0 | CB16: 0 | CC16: 0 | CD16: 0 | CE16: 0 | CF16: 0 | CG16: 0 | CH16: 0 | CI16: 0 | CJ16: 0 | CK16: 0 | CL16: 0 | CM16: 0 | CN16: 0 | CO16: 0 | CP16: 0 | CQ16: 0 | CR16: 0 | CS16: 0 | CT16: 0 | CU16: 0 | CV16: 0 | CW16: 0 | CX16: 0 | CY16: 0 | CZ16: 0 | DA16: 0 | DB16: 0 | DC16: 0 | DD16: 0 | DE16: 0 | DF16: 0 | DG16: 0 | DH16: 0 | DI16: 0 | DJ16: 0 | DK16: 0 | DL16: 0 | DM16: 0 | DN16: 0 | DO16: 0 | DP16: 0 | DQ16: 0 | DR16: 0 | DS16: 0 | DT16: 0 | DU16: 0 | DV16: 0 | DW16: 0 | DX16: 0 | DY16: 0 | DZ16: 0 | EA16: 0 | EB16: 0 | EC16: 0 | ED16: 0 | EE16: 0 | EF16: 0 | EG16: 0 | EH16: 0
E17: DT Meter | G17: Nos. | H17: =SUM(J17:EH17) -> 0 | J17: 0 | K17: 0 | L17: 0 | M17: 0 | N17: 0 | O17: 0 | P17: 0 | Q17: 0 | R17: 0 | S17: 0 | T17: 0 | U17: 0 | V17: 0 | W17: 0 | X17: 0 | Y17: 0 | Z17: 0 | AA17: 0 | AB17: 0 | AC17: 0 | AD17: 0 | AE17: 0 | AF17: 0 | AG17: 0 | AH17: 0 | AI17: 0 | AJ17: 0 | AK17: 0 | AL17: 0 | AM17: 0 | AN17: 0 | AO17: 0 | AP17: 0 | AQ17: 0 | AR17: 0 | AS17: 0 | AT17: 0 | AU17: 0 | AV17: 0 | AW17: 0 | AX17: 0 | AY17: 0 | AZ17: 0 | BA17: 0 | BB17: 0 | BC17: 0 | BD17: 0 | BE17: 0 | BF17: 0 | BG17: 0 | BH17: 0 | BI17: 0 | BJ17: 0 | BK17: 0 | BL17: 0 | BM17: 0 | BN17: 0 | BO17: 0 | BP17: 0 | BQ17: 0 | BR17: 0 | BS17: 0 | BT17: 0 | BU17: 0 | BV17: 0 | BW17: 0 | BX17: 0 | BY17: 0 | BZ17: 0 | CA17: 0 | CB17: 0 | CC17: 0 | CD17: 0 | CE17: 0 | CF17: 0 | CG17: 0 | CH17: 0 | CI17: 0 | CJ17: 0 | CK17: 0 | CL17: 0 | CM17: 0 | CN17: 0 | CO17: 0 | CP17: 0 | CQ17: 0 | CR17: 0 | CS17: 0 | CT17: 0 | CU17: 0 | CV17: 0 | CW17: 0 | CX17: 0 | CY17: 0 | CZ17: 0 | DA17: 0 | DB17: 0 | DC17: 0 | DD17: 0 | DE17: 0 | DF17: 0 | DG17: 0 | DH17: 0 | DI17: 0 | DJ17: 0 | DK17: 0 | DL17: 0 | DM17: 0 | DN17: 0 | DO17: 0 | DP17: 0 | DQ17: 0 | DR17: 0 | DS17: 0 | DT17: 0 | DU17: 0 | DV17: 0 | DW17: 0 | DX17: 0 | DY17: 0 | DZ17: 0 | EA17: 0 | EB17: 0 | EC17: 0 | ED17: 0 | EE17: 0 | EF17: 0 | EG17: 0 | EH17: 0
E18: Feeder Meter | G18: Nos. | H18: =SUM(J18:EH18) -> 0 | J18: 0 | K18: 0 | L18: 0 | M18: 0 | N18: 0 | O18: 0 | P18: 0 | Q18: 0 | R18: 0 | S18: 0 | T18: 0 | U18: 0 | V18: 0 | W18: 0 | X18: 0 | Y18: 0 | Z18: 0 | AA18: 0 | AB18: 0 | AC18: 0 | AD18: 0 | AE18: 0 | AF18: 0 | AG18: 0 | AH18: 0 | AI18: 0 | AJ18: 0 | AK18: 0 | AL18: 0 | AM18: 0 | AN18: 0 | AO18: 0 | AP18: 0 | AQ18: 0 | AR18: 0 | AS18: 0 | AT18: 0 | AU18: 0 | AV18: 0 | AW18: 0 | AX18: 0 | AY18: 0 | AZ18: 0 | BA18: 0 | BB18: 0 | BC18: 0 | BD18: 0 | BE18: 0 | BF18: 0 | BG18: 0 | BH18: 0 | BI18: 0 | BJ18: 0 | BK18: 0 | BL18: 0 | BM18: 0 | BN18: 0 | BO18: 0 | BP18: 0 | BQ18: 0 | BR18: 0 | BS18: 0 | BT18: 0 | BU18: 0 | BV18: 0 | BW18: 0 | BX18: 0 | BY18: 0 | BZ18: 0 | CA18: 0 | CB18: 0 | CC18: 0 | CD18: 0 | CE18: 0 | CF18: 0 | CG18: 0 | CH18: 0 | CI18: 0 | CJ18: 0 | CK18: 0 | CL18: 0 | CM18: 0 | CN18: 0 | CO18: 0 | CP18: 0 | CQ18: 0 | CR18: 0 | CS18: 0 | CT18: 0 | CU18: 0 | CV18: 0 | CW18: 0 | CX18: 0 | CY18: 0 | CZ18: 0 | DA18: 0 | DB18: 0 | DC18: 0 | DD18: 0 | DE18: 0 | DF18: 0 | DG18: 0 | DH18: 0 | DI18: 0 | DJ18: 0 | DK18: 0 | DL18: 0 | DM18: 0 | DN18: 0 | DO18: 0 | DP18: 0 | DQ18: 0 | DR18: 0 | DS18: 0 | DT18: 0 | DU18: 0 | DV18: 0 | DW18: 0 | DX18: 0 | DY18: 0 | DZ18: 0 | EA18: 0 | EB18: 0 | EC18: 0 | ED18: 0 | EE18: 0 | EF18: 0 | EG18: 0 | EH18: 0
B20: Auto-Computed
C21: GPRS & RF
E22: Consumer Meter | G22: Nos. | H22: =SUM(J22:EH22) -> 0 | J22: 0 | K22: 0 | L22: 0
E23: DT Meter | G23: Nos. | H23: =SUM(J23:EH23) -> 0 | J23: 0 | K23: 0 | L23: 0
E24: Feeder Meter | G24: Nos. | H24: =SUM(J24:EH24) -> 0 | J24: 0 | K24: 0 | L24: 0
C26: RF
E27: Consumer Meter | G27: Nos. | H27: =SUM(J27:EH27) -> 0 | J27: 0 | K27: 0 | L27: 0
E28: DT Meter | G28: Nos. | H28: =SUM(J28:EH28) -> 0 | J28: 0 | K28: 0 | L28: 0
E29: Feeder Meter | G29: Nos. | H29: =SUM(J29:EH29) -> 0 | J29: 0 | K29: 0 | L29: 0
B31: Selected Case
E32: Hardcoded/Auto computed option | F32: 1 | G32: Select | H32: 1: Hardcoded , 2 Auto computed
C34: GPRS & RF
E35: Consumer Meter | G35: Nos. | H35: =SUM(J35:EH35) -> 2620466 | J35: =CHOOSE($F$32, J11, J22 ) -> 0 | K35: =CHOOSE($F$32, K11, K22 ) -> 0 | L35: =CHOOSE($F$32, L11, L22 ) -> 0 | M35: =CHOOSE($F$32, M11, M22 ) -> 0 | N35: =CHOOSE($F$32, N11, N22 ) -> 0 | O35: =CHOOSE($F$32, O11, O22 ) -> 3 | P35: =CHOOSE($F$32, P11, P22 ) -> 15000 | Q35: =CHOOSE($F$32, Q11, Q22 ) -> 30000 | ... EH35: =CHOOSE($F$32, EH11, EH22 ) -> 0
E36: DT Meter | G36: Nos. | H36: =SUM(J36:EH36) -> 146932 | J36: =CHOOSE($F$32, J12, J23 ) -> 0 | K36: =CHOOSE($F$32, K12, K23 ) -> 0 | L36: =CHOOSE($F$32, L12, L23 ) -> 0 | M36: =CHOOSE($F$32, M12, M23 ) -> 0 | N36: =CHOOSE($F$32, N12, N23 ) -> 0 | O36: =CHOOSE($F$32, O12, O23 ) -> 41 | P36: =CHOOSE($F$32, P12, P23 ) -> 800 | Q36: =CHOOSE($F$32, Q12, Q23 ) -> 3000 | ... EH36: =CHOOSE($F$32, EH12, EH23 ) -> 0
E37: Feeder Meter | G37: Nos. | H37: =SUM(J37:EH37) -> 470 | J37: =CHOOSE($F$32, J13, J24 ) -> 0 | K37: =CHOOSE($F$32, K13, K24 ) -> 0 | L37: =CHOOSE($F$32, L13, L24 ) -> 0 | M37: =CHOOSE($F$32, M13, M24 ) -> 0 | N37: =CHOOSE($F$32, N13, N24 ) -> 0 | O37: =CHOOSE($F$32, O13, O24 ) -> 186 | P37: =CHOOSE($F$32, P13, P24 ) -> 84 | Q37: =CHOOSE($F$32, Q13, Q24 ) -> 200 | ... EH37: =CHOOSE($F$32, EH13, EH24 ) -> 0
C39: RF
E40: Consumer Meter | G40: Nos. | H40: =SUM(J40:EH40) -> 0 | J40: =CHOOSE($F$32, J16, J27 ) -> 0 | K40: =CHOOSE($F$32, K16, K27 ) -> 0 | L40: =CHOOSE($F$32, L16, L27 ) -> 0 | M40: =CHOOSE($F$32, M16, M27 ) -> 0 | N40: =CHOOSE($F$32, N16, N27 ) -> 0 | O40: =CHOOSE($F$32, O16, O27 ) -> 0 | P40: =CHOOSE($F$32, P16, P27 ) -> 0 | Q40: =CHOOSE($F$32, Q16, Q27 ) -> 0 | ... EH40: =CHOOSE($F$32, EH16, EH27 ) -> 0
E41: DT Meter | G41: Nos. | H41: =SUM(J41:EH41) -> 0 | J41: =CHOOSE($F$32, J17, J28 ) -> 0 | K41: =CHOOSE($F$32, K17, K28 ) -> 0 | L41: =CHOOSE($F$32, L17, L28 ) -> 0 | M41: =CHOOSE($F$32, M17, M28 ) -> 0 | N41: =CHOOSE($F$32, N17, N28 ) -> 0 | O41: =CHOOSE($F$32, O17, O28 ) -> 0 | P41: =CHOOSE($F$32, P17, P28 ) -> 0 | Q41: =CHOOSE($F$32, Q17, Q28 ) -> 0 | ... EH41: =CHOOSE($F$32, EH17, EH28 ) -> 0
E42: Feeder Meter | G42: Nos. | H42: =SUM(J42:EH42) -> 0 | J42: =CHOOSE($F$32, J18, J29 ) -> 0 | K42: =CHOOSE($F$32, K18, K29 ) -> 0 | L42: =CHOOSE($F$32, L18, L29 ) -> 0 | M42: =CHOOSE($F$32, M18, M29 ) -> 0 | N42: =CHOOSE($F$32, N18, N29 ) -> 0 | O42: =CHOOSE($F$32, O18, O29 ) -> 0 | P42: =CHOOSE($F$32, P18, P29 ) -> 0 | Q42: =CHOOSE($F$32, Q18, Q29 ) -> 0 | ... EH42: =CHOOSE($F$32, EH18, EH29 ) -> 0
A46: CAPEX PHASING
E48: AMI Equipment Cost | G48: % | H48: =SUM(TBA!J48:EH48) -> 1 | J48: =SUM(J11:J13)/SUM($H$11:$H$13) -> 0 | K48: =SUM(K11:K13)/SUM($H$11:$H$13) -> 0 | L48: =SUM(L11:L13)/SUM($H$11:$H$13) -> 0 | M48: =SUM(M11:M13)/SUM($H$11:$H$13) -> 0 | N48: =SUM(N11:N13)/SUM($H$11:$H$13) -> 0 | O48: =SUM(O11:O13)/SUM($H$11:$H$13) -> 8.3096448e-05 | P48: =SUM(P11:P13)/SUM($H$11:$H$13) -> 0.005738713 | Q48: =SUM(Q11:Q13)/SUM($H$11:$H$13) -> 0.011994792 | ... EH48: =SUM(EH11:EH13)/SUM($H$11:$H$13) -> 0
E49: Corporate, Consumer Indexing & Training | G49: % | H49: =SUM(TBA!J49:EH49) -> 1 | J49: =J48 -> 0 | K49: =K48 -> 0 | L49: =L48 -> 0 | M49: =M48 -> 0 | N49: =N48 -> 0 | O49: =O48 -> 8.3096448e-05 | P49: =P48 -> 0.005738713 | Q49: =Q48 -> 0.011994792 | ... EH49: =EH48 -> 0
E50: Advanced Metering Infrastructure (AMI) IT | G50: % | H50: =SUM(TBA!J50:EH50) -> 1 | J50: =J49 -> 0 | K50: =K49 -> 0 | L50: =L49 -> 0 | M50: =M49 -> 0 | N50: =N49 -> 0 | O50: =O49 -> 8.3096448e-05 | P50: =P49 -> 0.005738713 | Q50: =Q49 -> 0.011994792 | ... EH50: =EH49 -> 0
E51: Installation Charges | G51: % | H51: =SUM(TBA!J51:EH51) -> 1 | J51: =J50 -> 0 | K51: =K50 -> 0 | L51: =L50 -> 0 | M51: =M50 -> 0 | N51: =N50 -> 0 | O51: =O50 -> 8.3096448e-05 | P51: =P50 -> 0.005738713 | Q51: =Q50 -> 0.011994792 | ... EH51: =EH50 -> 0
E52: System Integration Charges | G52: % | H52: =SUM(TBA!J52:EH52) -> 1 | J52: =J51 -> 0 | K52: =K51 -> 0 | L52: =L51 -> 0 | M52: =M51 -> 0 | N52: =N51 -> 0 | O52: =O51 -> 8.3096448e-05 | P52: =P51 -> 0.005738713 | Q52: =Q51 -> 0.011994792 | ... EH52: =EH51 -> 0
...

Sheet Rollout
A1: =RIGHT(CELL("FILENAME", $A$1), LEN(CELL("FILENAME", $A$1)) - SEARCH("]", CELL("FILENAME", $A$1))) -> Rollout
E2: =Time_M!E$18 -> Model period beginning_M | J2: =Time_M!J$18 -> 45323 | K2: =Time_M!K$18 -> 45352 | L2: =Time_M!L$18 -> 45383 | M2: =Time_M!M$18 -> 45413 | N2: =Time_M!N$18 -> 45444 | O2: =Time_M!O$18 -> 45474 | P2: =Time_M!P$18 -> 45505 | Q2: =Time_M!Q$18 -> 45536 | ... EH2: =Time_M!EH$18 -> 49218
E3: =Time_M!E$22 -> Model period ending_M | F3: =Check!E$10 -> Model Check | G3: =Check!F$10 -> 0 | H3: =Check!G$10 -> check | J3: =Time_M!J$22 -> 45351 | K3: =Time_M!K$22 -> 45382 | L3: =Time_M!L$22 -> 45412 | M3: =Time_M!M$22 -> 45443 | N3: =Time_M!N$22 -> 45473 | O3: =Time_M!O$22 -> 45504 | P3: =Time_M!P$22 -> 45535 | Q3: =Time_M!Q$22 -> 45565 | ... EH3: =Time_M!EH$22 -> 49248
E4: =Time_M!E$35 -> Financial year ending period_M | J4: =Time_M!J$35 -> 45382 | K4: =Time_M!K$35 -> 45382 | L4: =Time_M!L$35 -> 45747 | M4: =Time_M!M$35 -> 45747 | N4: =Time_M!N$35 -> 45747 | O4: =Time_M!O$35 -> 45747 | P4: =Time_M!P$35 -> 45747 | Q4: =Time_M!Q$35 -> 45747 | ... EH4: =Time_M!EH$35 -> 49399
E5: =Time_M!E$32 -> Financial year ending_M | F5: Constant | G5: Unit | H5: Total | J5: =Time_M!J$32 -> 2024 | K5: =Time_M!K$32 -> 2024 | L5: =Time_M!L$32 -> 2025 | M5: =Time_M!M$32 -> 2025 | N5: =Time_M!N$32 -> 2025 | O5: =Time_M!O$32 -> 2025 | P5: =Time_M!P$32 -> 2025 | Q5: =Time_M!Q$32 -> 2025 | ... EH5: =Time_M!EH$32 -> 2035
A7: SMART ENERGY METERS
B9: Total smart meters installed
C10: GPRS & RF
E11: Consumer Meter | F11: =TBA!F$35 -> 0 | G11: =TBA!G$35 -> Nos. | H11: =TBA!H$35 -> 2620466 | I11: =TBA!I$35 -> 0 | J11: =TBA!J$35 -> 0 | K11: =TBA!K$35 -> 0 | L11: =TBA!L$35 -> 0 | M11: =TBA!M$35 -> 0 | ... EH11: =TBA!EH$35 -> 0
E12: DT Meter | F12: =TBA!F$36 -> 0 | G12: =TBA!G$36 -> Nos. | H12: =TBA!H$36 -> 146932 | I12: =TBA!I$36 -> 0 | J12: =TBA!J$36 -> 0 | K12: =TBA!K$36 -> 0 | L12: =TBA!L$36 -> 0 | M12: =TBA!M$36 -> 0 | ... EH12: =TBA!EH$36 -> 0
E13: Feeder Meter | F13: =TBA!F$37 -> 0 | G13: =TBA!G$37 -> Nos. | H13: =TBA!H$37 -> 470 | I13: =TBA!I$37 -> 0 | J13: =TBA!J$37 -> 0 | K13: =TBA!K$37 -> 0 | L13: =TBA!L$37 -> 0 | M13: =TBA!M$37 -> 0 | ... EH13: =TBA!EH$37 -> 0
C15: RF
E16: =TBA!E$40 -> Consumer Meter | F16: =TBA!F$40 -> 0 | G16: =TBA!G$40 -> Nos. | H16: =TBA!H$40 -> 0 | I16: =TBA!I$40 -> 0 | J16: =TBA!J$40 -> 0 | K16: =TBA!K$40 -> 0 | L16: =TBA!L$40 -> 0 | ... EH16: =TBA!EH$40 -> 0
E17: =TBA!E$41 -> DT Meter | F17: =TBA!F$41 -> 0 | G17: =TBA!G$41 -> Nos. | H17: =TBA!H$41 -> 0 | I17: =TBA!I$41 -> 0 | J17: =TBA!J$41 -> 0 | K17: =TBA!K$41 -> 0 | L17: =TBA!L$41 -> 0 | ... EH17: =TBA!EH$41 -> 0
E18: =TBA!E$42 -> Feeder Meter | F18: =TBA!F$42 -> 0 | G18: =TBA!G$42 -> Nos. | H18: =TBA!H$42 -> 0 | I18: =TBA!I$42 -> 0 | J18: =TBA!J$42 -> 0 | K18: =TBA!K$42 -> 0 | L18: =TBA!L$42 -> 0 | ... EH18: =TBA!EH$42 -> 0
E19: Total smart energy meters installed | G19: Nos | H19: =SUM(J19:EH19) -> 2767868 | J19: =SUM( J11:J13, J16:J18) -> 0 | K19: =SUM( K11:K13, K16:K18) -> 0 | L19: =SUM( L11:L13, L16:L18) -> 0 | M19: =SUM( M11:M13, M16:M18) -> 0 | N19: =SUM( N11:N13, N16:N18) -> 0 | O19: =SUM( O11:O13, O16:O18) -> 230 | P19: =SUM( P11:P13, P16:P18) -> 15884 | Q19: =SUM( Q11:Q13, Q16:Q18) -> 33200 | ... EH19: =SUM( EH11:EH13, EH16:EH18) -> 0
B21: Effective meters operational
E22: =NTBA!E$55 -> Min no. of meters for first billing | F22: =NTBA!F$55 -> 27678.68
E23: =E$19 -> Total smart energy meters installed | F23: =F$19 -> 0 | G23: =G$19 -> Nos | H23: =H$19 -> 2767868 | J23: =SUMIF($J$3:$EH$3,EOMONTH(Rollout!J3,-NTBA!$F$188),Rollout!$J$19:$EH$19) -> 0 | K23: =SUMIF($J$3:$EH$3,EOMONTH(Rollout!K3,-NTBA!$F$188),Rollout!$J$19:$EH$19) -> 0 | L23: =SUMIF($J$3:$EH$3,EOMONTH(Rollout!L3,-NTBA!$F$188),Rollout!$J$19:$EH$19) -> 0 | M23: =SUMIF($J$3:$EH$3,EOMONTH(Rollout!M3,-NTBA!$F$188),Rollout!$J$19:$EH$19) -> 0 | N23: =SUMIF($J$3:$EH$3,EOMONTH(Rollout!N3,-NTBA!$F$188),Rollout!$J$19:$EH$19) -> 0 | O23: =SUMIF($J$3:$EH$3,EOMONTH(Rollout!O3,-NTBA!$F$188),Rollout!$J$19:$EH$19) -> 0 | P23: =SUMIF($J$3:$EH$3,EOMONTH(Rollout!P3,-NTBA!$F$188),Rollout!$J$19:$EH$19) -> 0 | Q23: =SUMIF($J$3:$EH$3,EOMONTH(Rollout!Q3,-NTBA!$F$188),Rollout!$J$19:$EH$19) -> 230 | ... EH23: =SUMIF($J$3:$EH$3,EOMONTH(Rollout!EH3,-NTBA!$F$188),Rollout!$J$19:$EH$19) -> 0
E24: Min no. of meters for first billing | G24: flag | H24: =SUM(J24:EH24) -> 120 | J24: =IF( SUM( $J$23:J23 ) > $F22, 1, 0 ) -> 0 | K24: =IF( SUM( $J$23:K23 ) > $F22, 1, 0 ) -> 0 | L24: =IF( SUM( $J$23:L23 ) > $F22, 1, 0 ) -> 0 | M24: =IF( SUM( $J$23:M23 ) > $F22, 1, 0 ) -> 0 | N24: =IF( SUM( $J$23:N23 ) > $F22, 1, 0 ) -> 0 | O24: =IF( SUM( $J$23:O23 ) > $F22, 1, 0 ) -> 0 | P24: =IF( SUM( $J$23:P23 ) > $F22, 1, 0 ) -> 0 | Q24: =IF( SUM( $J$23:Q23 ) > $F22, 1, 0 ) -> 0 | ... EH24: =IF( SUM( $J$23:EH23 ) > $F22, 1, 0 ) -> 1
B26: First payment date
E27: =E$24 -> Min no. of meters for first billing | F27: =F$24 -> 0 | G27: =G$24 -> flag | H27: =H$24 -> 120 | I27: =I$24 -> 0 | J27: =J$24 -> 0 | K27: =K$24 -> 0 | L27: =L$24 -> 0 | ... EH27: =EH$24 -> 1
E28: 1st payment flag for meters | G28: flag | H28: =SUM(J28:EH28) -> 1 | J28: =J27 - I27 -> 0 | K28: =K27 - J27 -> 0 | L28: =L27 - K27 -> 0 | M28: =M27 - L27 -> 0 | N28: =N27 - M27 -> 0 | O28: =O27 - N27 -> 0 | P28: =P27 - O27 -> 0 | Q28: =Q27 - P27 -> 0 | ... EH28: =EH27 - EG27 -> 0
E29: =Time_M!E$22 -> Model period ending_M | F29: =Time_M!F$22 -> 0 | G29: =Time_M!G$22 -> date | H29: =Time_M!H$22 -> 0 | I29: =Time_M!I$22 -> 0 | J29: =Time_M!J$22 -> 45351 | K29: =Time_M!K$22 -> 45382 | L29: =Time_M!L$22 -> 45412 | ... EH29: =Time_M!EH$22 -> 49248
E30: 1st payment date for meters | G30: date | J30: =IF( J28 = 1, J29, "") | K30: =IF( K28 = 1, K29, "") | L30: =IF( L28 = 1, L29, "") | M30: =IF( M28 = 1, M29, "") | N30: =IF( N28 = 1, N29, "") | O30: =IF( O28 = 1, O29, "") | P30: =IF( P28 = 1, P29, "") | Q30: =IF( Q28 = 1, Q29, "") | ... EH30: =IF( EH28 = 1, EH29, "")
E31: Month min number of meters installed for 1st Payment | F31: =INDEX(J28:EH30,2,MATCH(1,J28:EH28,0)) -> 45626 | G31: date
E33: =NTBA!E$35 -> Total number of meter months for billing for SBD | F33: =NTBA!F$35 -> 257411724 | G33: =NTBA!G$35 -> Nos.
E34: =Time_M!E$64 -> Implementation Period Flag | F34: =Time_M!F$64 -> 0 | G34: =Time_M!G$64 -> flag | H34: =Time_M!H$64 -> 124 | I34: =Time_M!I$64 -> 0 | J34: =Time_M!J$64 -> 0 | K34: =Time_M!K$64 -> 0 | L34: =Time_M!L$64 -> 0 | ... EH34: =Time_M!EH$64 -> 1
E35: =E$19 -> Total smart energy meters installed | F35: =F$19 -> 0 | G35: =G$19 -> Nos | H35: =H$19 -> 2767868 | I35: =I$19 -> 0 | J35: =SUMIF($J$3:$EH$3,EOMONTH(Rollout!J3,-NTBA!$F$188),Rollout!$J$19:$EH$19) -> 0 | K35: =SUMIF($J$3:$EH$3,EOMONTH(Rollout!K3,-NTBA!$F$188),Rollout!$J$19:$EH$19) -> 0 | L35: =SUMIF($J$3:$EH$3,EOMONTH(Rollout!L3,-NTBA!$F$188),Rollout!$J$19:$EH$19) -> 0 | M35: =SUMIF($J$3:$EH$3,EOMONTH(Rollout!M3,-NTBA!$F$188),Rollout!$J$19:$EH$19) -> 0 | N35: =SUMIF($J$3:$EH$3,EOMONTH(Rollout!N3,-NTBA!$F$188),Rollout!$J$19:$EH$19) -> 0 | O35: =SUMIF($J$3:$EH$3,EOMONTH(Rollout!O3,-NTBA!$F$188),Rollout!$J$19:$EH$19) -> 0 | P35: =SUMIF($J$3:$EH$3,EOMONTH(Rollout!P3,-NTBA!$F$188),Rollout!$J$19:$EH$19) -> 0 | Q35: =SUMIF($J$3:$EH$3,EOMONTH(Rollout!Q3,-NTBA!$F$188),Rollout!$J$19:$EH$19) -> 230 | ... EH35: =SUMIF($J$3:$EH$3,EOMONTH(Rollout!EH3,-NTBA!$F$188),Rollout!$J$19:$EH$19) -> 0
E37: Effective Meters Operational | G37: Nos | J37: =IF( J$34, MIN( $F33 - SUM( I$39:$I39 ), SUM( $I$35:J35 )), SUM( I$35:$J35 )) -> 0 | K37: =IF( K$34, MIN( $F33 - SUM( $I$39:J39 ), SUM( $I$35:K35 )), SUM( J$35:$J35 )) -> 0 | L37: =IF( L$34, MIN( $F33 - SUM( $I$39:K39 ), SUM( $I$35:L35 )), SUM( $J$35:K35 )) -> 0 | M37: =IF( M$34, MIN( $F33 - SUM( $I$39:L39 ), SUM( $I$35:M35 )), SUM( $J$35:L35 )) -> 0 | N37: =IF( N$34, MIN( $F33 - SUM( $I$39:M39 ), SUM( $I$35:N35 )), SUM( $J$35:M35 )) -> 0 | O37: =IF( O$34, MIN( $F33 - SUM( $I$39:N39 ), SUM( $I$35:O35 )), SUM( $J$35:N35 )) -> 0 | P37: =IF( P$34, MIN( $F33 - SUM( $I$39:O39 ), SUM( $I$35:P35 )), SUM( $J$35:O35 )) -> 0 | Q37: =IF( Q$34, MIN( $F33 - SUM( $I$39:P39 ), SUM( $I$35:Q35 )), SUM( $J$35:P35 )) -> 230 | R37: =IF( R$34, MIN( $F33 - SUM( $I$39:Q39 ), SUM( $I$35:R35 )), SUM( $J$35:Q35 )) -> 16114 | S37: =IF( S$34, MIN( $F33 - SUM( $I$39:R39 ), SUM( $I$35:S35 )), SUM( $J$35:R35 )) -> 49314 | ... EH37: =IF( EH$34, MIN( $F33 - SUM( $I$39:EG39 ), SUM( $I$35:EH35 )), SUM( $J$35:EG35 )) -> 0
E38: Effective Meters Operational for Opex cost | G38: Nos | J38: =MAX( MIN( $F33 - SUM( $I$38:I38 ), J37 ),0) -> 0 | K38: =MAX( MIN( $F33 - SUM( $I$38:J38 ), K37 ),0) -> 0 | L38: =MAX( MIN( $F33 - SUM( $I$38:K38 ), L37 ),0) -> 0 | M38: =MAX( MIN( $F33 - SUM( $I$38:L38 ), M37 ),0) -> 0 | N38: =MAX( MIN( $F33 - SUM( $I$38:M38 ), N37 ),0) -> 0 | O38: =MAX( MIN( $F33 - SUM( $I$38:N38 ), O37 ),0) -> 0 | P38: =MAX( MIN( $F33 - SUM( $I$38:O38 ), P37 ),0) -> 0 | Q38: =MAX( MIN( $F33 - SUM( $I$38:P38 ), Q37 ),0) -> 230 | ... DQ38: =MAX( MIN( $F33 - SUM( $I$38:DP38 ), DQ37 ),0) -> 2767868 | DR38: =DQ38 -> 2767868 | DS38: =MAX( MIN( $F33 - SUM( $I$38:DR38 ), DS37 ),0) -> 0 | DT38: =MAX( MIN( $F33 - SUM( $I$38:DS38 ), DT37 ),0) -> 0 | DU38: =MAX( MIN( $F33 - SUM( $I$38:DT38 ), DU37 ),0) -> 0 | DV38: =MAX( MIN( $F33 - SUM( $I$38:DU38 ), DV37 ),0) -> 0 | DW38: =MAX( MIN( $F33 - SUM( $I$38:DV38 ), DW37 ),0) -> 0 | DX38: =MAX( MIN( $F33 - SUM( $I$38:DW38 ), DX37 ),0) -> 0 | DY38: =MAX( MIN( $F33 - SUM( $I$38:DX38 ), DY37 ),0) -> 0 | DZ38: =MAX( MIN( $F33 - SUM( $I$38:DY38 ), DZ37 ),0) -> 0 | ... EH38: =MAX( MIN( $F33 - SUM( $I$38:EG38 ), EH37 ),0) -> 0
E39: Effective Meters Operational and billed | G39: Nos | J39: =IF(J3=$F$31,J37,IF(J3>$F$31,J37,0)) -> 0 | K39: =IF(K3=$F$31,K37,IF(K3>$F$31,K37,0)) -> 0 | L39: =IF(L3=$F$31,L37,IF(L3>$F$31,L37,0)) -> 0 | M39: =IF(M3=$F$31,M37,IF(M3>$F$31,M37,0)) -> 0 | N39: =IF(N3=$F$31,N37,IF(N3>$F$31,N37,0)) -> 0 | O39: =IF(O3=$F$31,O37,IF(O3>$F$31,O37,0)) -> 0 | P39: =IF(P3=$F$31,P37,IF(P3>$F$31,P37,0)) -> 0 | Q39: =IF(Q3=$F$31,Q37,IF(Q3>$F$31,Q37,0)) -> 0 | ... EH39: =IF(EH3=$F$31,EH37,IF(EH3>$F$31,EH37,0)) -> 0
E40: Cumulative Operational Meter Months | G40: Nos | J40: =IF( J39 > 0, SUM( $J$39:J39 ), 0 ) -> 0 | K40: =IF( K39 > 0, SUM( $J$39:K39 ), 0 ) -> 0 | L40: =IF( L39 > 0, SUM( $J$39:L39 ), 0 ) -> 0 | M40: =IF( M39 > 0, SUM( $J$39:M39 ), 0 ) -> 0 | N40: =IF( N39 > 0, SUM( $J$39:N39 ), 0 ) -> 0 | O40: =IF( O39 > 0, SUM( $J$39:O39 ), 0 ) -> 0 | P40: =IF( P39 > 0, SUM( $J$39:P39 ), 0 ) -> 0 | Q40: =IF( Q39 > 0, SUM( $J$39:Q39 ), 0 ) -> 0 | ... EH40: =IF( EH39 > 0, SUM( $J$39:EH39 ), 0 ) -> 0
E42: =NTBA!E$35 -> Total number of meter months for billing for SBD | F42: =NTBA!F$35 -> 257411724 | G42: =NTBA!G$35 -> Nos.
E43: =E40 -> Cumulative Operational Meter Months | F43: =F40 -> 0 | G43: =G40 -> Nos | H43: =H40 -> 0 | I43: =I40 -> 0 | J43: =J40 -> 0 | K43: =K40 -> 0 | L43: =L40 -> 0 | ... EH43: =EH40 -> 0
E44: SBD billing flag | G44: flag | H44: =SUM(J44:EH44) -> 1 | J44: =IF( J43 = $F42, 1, 0) -> 0 | K44: =IF( K43 = $F42, 1, 0) -> 0 | L44: =IF( L43 = $F42, 1, 0) -> 0 | M44: =IF( M43 = $F42, 1, 0) -> 0 | N44: =IF( N43 = $F42, 1, 0) -> 0 | O44: =IF( O43 = $F42, 1, 0) -> 0 | P44: =IF( P43 = $F42, 1, 0) -> 0 | Q44: =IF( Q43 = $F42, 1, 0) -> 0 | ... EH44: =IF( EH43 = $F42, 1, 0) -> 0
E45: =Time_M!E$22 -> Model period ending_M | F45: =Time_M!F$22 -> 0 | G45: =Time_M!G$22 -> date | H45: =Time_M!H$22 -> 0 | I45: =Time_M!I$22 -> 0 | J45: =Time_M!J$22 -> 45351 | K45: =Time_M!K$22 -> 45382 | L45: =Time_M!L$22 -> 45412 | ... EH45: =Time_M!EH$22 -> 49248
E46: Contract End Date | F46: =INDEX(M44:EH46,2,MATCH(1,M44:EH44,0)) -> 48760 | G46: date | J46: =IF( J44 = 1, J45,"") | K46: =IF( K44 = 1, K45,"") | L46: =IF( L44 = 1, L45,"") | M46: =IF( M44 = 1, M45,"") | N46: =IF( N44 = 1, N45,"") | O46: =IF( O44 = 1, O45,"") | P46: =IF( P44 = 1, P45,"") | Q46: =IF( Q44 = 1, Q45,"") | ... EH46: =IF( EH44 = 1, EH45,"")
A49: PAYMENT FROM DISCOM (EXCL. SERVICE CHARGES)
B51: Upfront payments - per meter
...

Sheet Monthly Financials
A1: =RIGHT(CELL("FILENAME", $A$1), LEN(CELL("FILENAME", $A$1)) - SEARCH("]", CELL("FILENAME", $A$1))) -> Monthly Financials
E2: =Time_M!E$18 -> Model period beginning_M | J2: =Time_M!J$18 -> 45323 | K2: =Time_M!K$18 -> 45352 | L2: =Time_M!L$18 -> 45383 | M2: =Time_M!M$18 -> 45413 | N2: =Time_M!N$18 -> 45444 | O2: =Time_M!O$18 -> 45474 | P2: =Time_M!P$18 -> 45505 | Q2: =Time_M!Q$18 -> 45536 | ... EH2: =Time_M!EH$18 -> 49218
E3: =Time_M!E$22 -> Model period ending_M | F3: =Check!E$10 -> Model Check | G3: =Check!F$10 -> 0 | H3: =Check!G$10 -> check | J3: =Time_M!J$22 -> 45351 | K3: =Time_M!K$22 -> 45382 | L3: =Time_M!L$22 -> 45412 | M3: =Time_M!M$22 -> 45443 | N3: =Time_M!N$22 -> 45473 | O3: =Time_M!O$22 -> 45504 | P3: =Time_M!P$22 -> 45535 | Q3: =Time_M!Q$22 -> 45565 | ... EH3: =Time_M!EH$22 -> 49248
E4: =Time_M!E$35 -> Financial year ending period_M | J4: =Time_M!J$35 -> 45382 | K4: =Time_M!K$35 -> 45382 | L4: =Time_M!L$35 -> 45747 | M4: =Time_M!M$35 -> 45747 | N4: =Time_M!N$35 -> 45747 | O4: =Time_M!O$35 -> 45747 | P4: =Time_M!P$35 -> 45747 | Q4: =Time_M!Q$35 -> 45747 | ... EH4: =Time_M!EH$35 -> 49399
E5: =Time_M!E$32 -> Financial year ending_M | F5: Constant | G5: Unit | H5: Total | J5: =Time_M!J$32 -> 2024 | K5: =Time_M!K$32 -> 2024 | L5: =Time_M!L$32 -> 2025 | M5: =Time_M!M$32 -> 2025 | N5: =Time_M!N$32 -> 2025 | O5: =Time_M!O$32 -> 2025 | P5: =Time_M!P$32 -> 2025 | Q5: =Time_M!Q$32 -> 2025 | ... EH5: =Time_M!EH$32 -> 2035
A7: REVENUE - MONTHLY
B9: Revenue (On Accounting Basis)
C10: Upfront payment - Discom
E11: =Rollout!E85 -> Payment from DISCOM (Upfront) | F11: =Rollout!F85 -> 0 | G11: =Rollout!G85 -> INR Cr | H11: =SUM(J11:EH11) -> 243.07592 | J11: =Rollout!J85 -> 0 | K11: =Rollout!K85 -> 0 | L11: =Rollout!L85 -> 0 | M11: =Rollout!M85 -> 0 | N11: =Rollout!N85 -> 0 | O11: =Rollout!O85 -> 0 | P11: =Rollout!P85 -> 0 | Q11: =Rollout!Q85 -> 0 | ... EH11: =Rollout!EH85 -> 0
E12: =Rollout!E86 -> Payment from DISCOM (Cable) | F12: =Rollout!F86 -> 0 | G12: =Rollout!G86 -> INR Cr | H12: =SUM(J12:EH12) -> 196.13901 | J12: =Rollout!J84 -> 0 | K12: =Rollout!K84 -> 0 | L12: =Rollout!L84 -> 0 | M12: =Rollout!M84 -> 0 | N12: =Rollout!N84 -> 0 | O12: =Rollout!O84 -> 0 | P12: =Rollout!P84 -> 0 | Q12: =Rollout!Q84 -> 3.4945304 | ... EH12: =Rollout!EH84 -> 0
E13: =Time_M!E88 -> Upfront flag | F13: =Time_M!F88 -> 0 | G13: =Time_M!G88 -> flag | H13: =Time_M!H88 -> 113 | J13: =Time_M!J88 -> 1 | K13: =Time_M!K88 -> 1 | L13: =Time_M!L88 -> 1 | M13: =Time_M!M88 -> 1 | N13: =Time_M!N88 -> 1 | O13: =Time_M!O88 -> 1 | P13: =Time_M!P88 -> 1 | Q13: =Time_M!Q88 -> 1 | ... EH13: =Time_M!EH88 -> 0
E14: Upfront Payment by DISCOM | G14: INR Cr | H14: =SUM(J14:EH14) -> 439.21492 | J14: =( J12+J11) * J13 -> 0 | K14: =( K12+K11) * K13 -> 0 | L14: =( L12+L11) * L13 -> 0 | M14: =( M12+M11) * M13 -> 0 | N14: =( N12+N11) * N13 -> 0 | O14: =( O12+O11) * O13 -> 0 | P14: =( P12+P11) * P13 -> 0 | Q14: =( Q12+Q11) * Q13 -> 3.4945304 | ... EH14: =( EH12+EH11) * EH13 -> 0
D16: Upfront payment ratio
E17: =Capex!E$72 -> Total capex | F17: =Capex!F$72 -> 1248.9083 | G17: =Capex!G$72 -> INR Cr
E18: =E$14 -> Upfront Payment by DISCOM | F18: =F$14 -> 0 | G18: =G$14 -> INR Cr | H18: =H$14 -> 439.21492 | J18: =J$14 -> 0 | K18: =K$14 -> 0 | L18: =L$14 -> 0 | M18: =M$14 -> 0 | N18: =N$14 -> 0 | O18: =O$14 -> 0 | P18: =P$14 -> 0 | Q18: =Q$14 -> 3.4945304 | ... EH18: =EH$14 -> 0
E19: Upfront payment ratio | F19: =H18 / $F$17 -> 0.35167908 | G19: ratio
C21: AMISP Service Charge on Meters Installed
E22: =NTBA!E$39 -> Qouted - Avg. Service Charge (PMPM) | F22: =NTBA!F$39 -> 79.560181 | G22: =NTBA!G$39 -> INR / meter / month
E23: =NTBA!E$302 -> Conversion to Crores | F23: =NTBA!F$302 -> 10000000 | G23: =NTBA!G$302 -> Crores
E24: =Rollout!E39 -> Effective Meters Operational and billed | F24: =Rollout!F39 -> 0 | G24: =Rollout!G39 -> Nos | H24: =Rollout!H39 -> 0 | I24: =Rollout!I39 -> 0 | J24: =Rollout!J39 -> 0 | K24: =Rollout!K39 -> 0 | L24: =Rollout!L39 -> 0 | ... EH24: =Rollout!EH39 -> 0
E25: =Time_M!E$88 -> Upfront flag | F25: =Time_M!F$88 -> 0 | G25: =Time_M!G$88 -> flag | H25: =Time_M!H$88 -> 113 | I25: =Time_M!I$88 -> 0 | J25: =Time_M!J$88 -> 1 | K25: =Time_M!K$88 -> 1 | L25: =Time_M!L$88 -> 1 | ... EH25: =Time_M!EH$88 -> 0
E26: AMISP Service Charge on Meters Installed | G26: INR Cr | H26: =SUM(J26:EH26) -> 2047.9723 | J26: =( $F22 * J24 / $F23 ) * J25 -> 0 | K26: =( $F22 * K24 / $F23 ) * K25 -> 0 | L26: =( $F22 * L24 / $F23 ) * L25 -> 0 | M26: =( $F22 * M24 / $F23 ) * M25 -> 0 | N26: =( $F22 * N24 / $F23 ) * N25 -> 0 | O26: =( $F22 * O24 / $F23 ) * O25 -> 0 | P26: =( $F22 * P24 / $F23 ) * P25 -> 0 | Q26: =( $F22 * Q24 / $F23 ) * Q25 -> 0 | ... EH26: =( $F22 * EH24 / $F23 ) * EH25 -> 0
C28: Revenue Summary
E29: =E11 -> Payment from DISCOM (Upfront) | F29: ='Monthly Financials'!F$14 -> 0 | G29: ='Monthly Financials'!G$14 -> INR Cr | H29: =SUM(J29:EH29) -> 243.07592 | I29: ='Monthly Financials'!I$14 -> 0 | J29: =J11 -> 0 | K29: =K11 -> 0 | L29: =L11 -> 0 | M29: =M11 -> 0 | N29: =N11 -> 0 | O29: =O11 -> 0 | P29: =P11 -> 0 | Q29: =Q11 -> 0 | ... EH29: =EH11 -> 0
E30: =E12 -> Payment from DISCOM (Cable) | F30: ='Monthly Financials'!F$14 -> 0 | G30: ='Monthly Financials'!G$14 -> INR Cr | H30: =SUM(J30:EH30) -> 196.13901 | I30: ='Monthly Financials'!I$14 -> 0 | J30: =J12 -> 0 | K30: =K12 -> 0 | L30: =L12 -> 0 | M30: =M12 -> 0 | N30: =N12 -> 0 | O30: =O12 -> 0 | P30: =P12 -> 0 | Q30: =Q12 -> 3.4945304 | ... EH30: =EH12 -> 0
E31: =E$26 -> AMISP Service Charge on Meters Installed | F31: =F$26 -> 0 | G31: =G$26 -> INR Cr | H31: =H$26 -> 2047.9723 | I31: =I$26 -> 0 | J31: =J$26 -> 0 | K31: =K$26 -> 0 | L31: =L$26 -> 0 | ... EH31: =EH$26 -> 0
E32: Total Revenue excl GST | G32: INR Cr | H32: =SUM(J32:EH32) -> 2487.1873 | J32: =SUM(J29:J31) -> 0 | K32: =SUM(K29:K31) -> 0 | L32: =SUM(L29:L31) -> 0 | M32: =SUM(M29:M31) -> 0 | N32: =SUM(N29:N31) -> 0 | O32: =SUM(O29:O31) -> 0 | P32: =SUM(P29:P31) -> 0 | Q32: =SUM(Q29:Q31) -> 3.4945304 | ... EH32: =SUM(EH29:EH31) -> 0
E34: =NTBA!E$40 -> GST on AMISP Service Charge (In %) | F34: =NTBA!F$40 -> 0.18 | G34: =NTBA!G$40 -> %
E35: =E$32 -> Total Revenue excl GST | F35: =F$32 -> 0 | G35: =G$32 -> INR Cr | H35: =H$32 -> 2487.1873 | I35: =I$32 -> 0 | J35: =J$32 -> 0 | K35: =K$32 -> 0 | L35: =L$32 -> 0 | ... EH35: =EH$32 -> 0
E36: GST on revenue | G36: INR Cr | H36: =SUM(J36:EH36) -> 447.69371 | I36: =I$32 -> 0 | J36: =$F34 * J35 -> 0 | K36: =$F34 * K35 -> 0 | L36: =$F34 * L35 -> 0 | M36: =$F34 * M35 -> 0 | N36: =$F34 * N35 -> 0 | O36: =$F34 * O35 -> 0 | P36: =$F34 * P35 -> 0 | Q36: =$F34 * Q35 -> 0.62901547 | ... EH36: =$F34 * EH35 -> 0
E38: ='Monthly Financials'!E$32 -> Total Revenue excl GST | F38: ='Monthly Financials'!F$32 -> 0 | G38: ='Monthly Financials'!G$32 -> INR Cr | H38: ='Monthly Financials'!H$32 -> 2487.1873 | I38: ='Monthly Financials'!I$32 -> 0 | J38: ='Monthly Financials'!J$32 -> 0 | K38: ='Monthly Financials'!K$32 -> 0 | L38: ='Monthly Financials'!L$32 -> 0 | ... EH38: ='Monthly Financials'!EH$32 -> 0
E39: ='Monthly Financials'!E$36 -> GST on revenue | F39: ='Monthly Financials'!F$36 -> 0 | G39: ='Monthly Financials'!G$36 -> INR Cr | H39: ='Monthly Financials'!H$36 -> 447.69371 | I39: ='Monthly Financials'!I$36 -> 0 | J39: ='Monthly Financials'!J$36 -> 0 | K39: ='Monthly Financials'!K$36 -> 0 | L39: ='Monthly Financials'!L$36 -> 0 | ... EH39: ='Monthly Financials'!EH$36 -> 0
E40: Total Revenue incl. GST (On Accounting Basis) | G40: INR Cr | H40: =SUM(J40:EH40) -> 2934.881 | J40: =SUM(J38:J39) -> 0 | K40: =SUM(K38:K39) -> 0 | L40: =SUM(L38:L39) -> 0 | M40: =SUM(M38:M39) -> 0 | N40: =SUM(N38:N39) -> 0 | O40: =SUM(O38:O39) -> 0 | P40: =SUM(P38:P39) -> 0 | Q40: =SUM(Q38:Q39) -> 4.1235459 | ... EH40: =SUM(EH38:EH39) -> 0
B42: Total Revenue (On Cash Basis)
C43: Upfront Payment by DISCOM
E44: =NTBA!E$48 -> First Payment | F44: =NTBA!F$48 -> 0 | G44: =NTBA!G$48 -> months
E45: =NTBA!E$43 -> First Payment | F45: =NTBA!F$43 -> 1 | G45: =NTBA!G$43 -> %
E46: =Time_M!E$9 -> Model column counter | F46: =Time_M!F$9 -> 0 | G46: =Time_M!G$9 -> counter | H46: =Time_M!H$107 -> 0 | I46: =Time_M!I$107 -> 0 | J46: =Time_M!J$9 -> 1 | K46: =Time_M!K$9 -> 2 | L46: =Time_M!L$9 -> 3 | M46: =Time_M!M$9 -> 4 | N46: =Time_M!N$9 -> 5 | O46: =Time_M!O$9 -> 6 | P46: =Time_M!P$9 -> 7 | Q46: =Time_M!Q$9 -> 8 | ... EH46: =Time_M!EH$9 -> 129
E47: =E11 -> Payment from DISCOM (Upfront) | F47: ='Monthly Financials'!F$14 -> 0 | G47: ='Monthly Financials'!G$14 -> INR Cr | H47: =SUM(J47:EH47) -> 243.07592 | J47: =J11 -> 0 | K47: =K11 -> 0 | L47: =L11 -> 0 | M47: =M11 -> 0 | N47: =N11 -> 0 | O47: =O11 -> 0 | P47: =P11 -> 0 | Q47: =Q11 -> 0 | ... EH47: =EH11 -> 0
E48: =E12 -> Payment from DISCOM (Cable) | F48: ='Monthly Financials'!F$14 -> 0 | G48: ='Monthly Financials'!G$14 -> INR Cr | H48: =SUM(J48:EH48) -> 196.13901 | I48: ='Monthly Financials'!I$14 -> 0 | J48: =J12 -> 0 | K48: =K12 -> 0 | L48: =L12 -> 0 | M48: =M12 -> 0 | N48: =N12 -> 0 | O48: =O12 -> 0 | P48: =P12 -> 0 | Q48: =Q12 -> 3.4945304 | ... EH48: =EH12 -> 0
...

Sheet Ind AS Monthly
A1: =RIGHT(CELL("FILENAME", $A$1), LEN(CELL("FILENAME", $A$1)) - SEARCH("]", CELL("FILENAME", $A$1))) -> Ind AS Monthly
E2: =Time_M!E$18 -> Model period beginning_M | J2: =Time_M!J$18 -> 45323 | K2: =Time_M!K$18 -> 45352 | L2: =Time_M!L$18 -> 45383 | M2: =Time_M!M$18 -> 45413 | N2: =Time_M!N$18 -> 45444 | O2: =Time_M!O$18 -> 45474 | P2: =Time_M!P$18 -> 45505 | Q2: =Time_M!Q$18 -> 45536 | ... EH2: =Time_M!EH$18 -> 49218
